Workbook

Sheet Sheet1
A1: Timestamp | B1: Age | C1: Gender | D1: Marital Status | E1: Which state in the US did you primarily grow up in, or which country? | F1: Have you lived in a country other than the US for more than 3 months? | G1: If you answered 'Yes' to the previous question, where did you live? | H1: Are you currently a student? | I1: How often did you experience extreme or disruptive weather where you grew up? | J1: Which statement best describes the difference between weather and climate? | K1: List your 3 most used forms of transportation on a normal day | L1: Form 2 | M1: Form 3 | N1: How easy is it for you to reach your normal daily destinations (school, work, shopping)? | O1: In middle school, how many students were in a typical class? | P1: If you grew up in Utah, which county? | Q1: Comments and notes | R1: Place of Origin Given this Information
A2: 46163.703 | B2: 25+ | C2: Male | D2: Married | E2: Utah | F2: Yes | G2: Germany, S. Korea, Afghanistan | H2: No | I2: Sometimes | J2: Weather is short-term atmospheric conditions, while climate is long-term patterns over time. | K2: Car | N2: Very Easy | O2: 26-30 students | P2: Davis | Q2: He says he is from Davis County, Utah | R2: Davis
A3: 46163.705 | B3: 25+ | C3: Male | D3: Married | E3: Utah | F3: No | G3: United States of America | H3: No | I3: Rarely | J3: Weather is short-term atmospheric conditions, while climate is long-term patterns over time. | K3: Car | N3: Very Easy | O3: 26-30 students | P3: Sanpete | Q3: He only grew up in America, specifically Sanpete County | R3: Sanpete
A4: 46163.716 | B4: 25+ | C4: Female | D4: Married | E4: California | F4: No | G4: No | H4: No | I4: Rarely | J4: Weather is short-term atmospheric conditions, while climate is long-term patterns over time. | K4: Car, | L4: Walking, | M4: Rideshare (Uber/Lyft) | N4: Very Easy | O4: 26-30 students | P4: I did not grow up in the state of Utah | Q4: She is from California | R4: California
A5: 46163.723 | B5: 21-22 | C5: Male | D5: Single | E5: California | F5: Yes | G5: Brazil | H5: Yes | I5: Rarely | J5: Weather is short-term atmospheric conditions, while climate is long-term patterns over time. | K5: Public transportation (Bus, Train, shuttle, tram, etc.), | L5: Walking, | M5: Biking | N5: Somewhat Easy | O5: 31-35 students | P5: I did not grow up in the state of Utah | Q5: This person grew up in California | R5: California
A6: 46163.734 | B6: 25+ | C6: Male | D6: Married | E6: California | F6: Yes | G6: Kuwait, Phillipines, Afghanistan | H6: No | I6: Rarely | J6: Weather is short-term atmospheric conditions, while climate is long-term patterns over time. | K6: Car, | L6: Walking | N6: Very Easy | O6: 21-25 students | P6: I did not grow up in the state of Utah | Q6: This person was from California during his childhood | R6: California
A7: 46163.737 | B7: 25+ | C7: Male | D7: Married | E7: New york | F7: Yes | G7: Iraq and afghanistan | H7: Yes | I7: Sometimes | J7: Weather is short-term atmospheric conditions, while climate is long-term patterns over time. | K7: Car | N7: Somewhat Easy | O7: 21-25 students | P7: I did not grow up in the state of Utah | Q7: He was from New York | R7: New York
A8: 46163.738 | B8: 25+ | C8: Female | D8: Married | E8: Canada | F8: Yes | G8: Raymond, Alberta, Canada | H8: No | I8: Often | J8: Weather is short-term atmospheric conditions, while climate is long-term patterns over time. | K8: Car, | L8: Walking | N8: Very Easy | O8: 26-30 students | P8: I did not grow up in the state of Utah | Q8: She was from Canada and did not grow up in America at all | R8: Foreign Country
A9: 46163.74 | B9: 25+ | C9: Female | D9: Married | E9: Uta | F9: No | G9: N/a | H9: No | I9: Rarely | J9: Weather is short-term atmospheric conditions, while climate is long-term patterns over time. | K9: Car, , | L9: Public transportation (Bus, Train, shuttle, tram, etc.) | M9: Walking | N9: Very Easy | O9: 16-20 students | P9: Salt Lake | Q9: She accidentally wrote she grew up in "Uta" like the busses, but this was a misspelling of "Utah" | R9: Salt Lake
A10: 46163.741 | B10: 25+ | C10: Male | D10: Married | E10: Arizona | F10: Yes | G10: Japan | H10: No | I10: Rarely | J10: Weather is short-term atmospheric conditions, while climate is long-term patterns over time. | K10: Car, , | L10: Walking | M10: other | N10: Somewhat Easy | O10: 26-30 students | P10: I did not grow up in the state of Utah | Q10: He could have grown up in Lake Havasu, Arizona | R10: Lake Havasu, Arizona
A11: 46163.741 | B11: 25+ | C11: Female | D11: Married | E11: Jersey City | F11: No | G11: N/a | H11: No | I11: Very often | J11: Not sure. | K11: Car, | L11: Walking | N11: Somewhat Easy | O11: 26-30 students | P11: I did not grow up in the state of Utah | Q11: Jersey City could possibly be in New Jersey, America | R11: New Jersey
A12: 46163.746 | B12: 25+ | C12: Female | D12: Single | E12: NY | F12: No | G12: NA | H12: No | I12: Rarely | J12: Weather is short-term atmospheric conditions, while climate is long-term patterns over time. | K12: Car, Walking, Other | N12: Very Easy | O12: 26-30 students | P12: I did not grow up in the state of Utah | Q12: "NY" means New York | R12: New York
A13: 46163.746 | B13: 19-20 | C13: Female | D13: Single | E13: California | F13: No | G13: N/A | H13: Yes | I13: Rarely | J13: Weather is short-term atmospheric conditions, while climate is long-term patterns over time. | K13: Public transportation (Bus, Train, shuttle, tram, etc.), Walking | N13: Somewhat Easy | O13: 26-30 students | P13: I did not grow up in the state of Utah | Q13: She is from California | R13: California
A14: 46163.747 | B14: 25+ | C14: Female | D14: Married | E14: California | F14: No | G14: NA | H14: No | I14: Rarely | J14: Weather is short-term atmospheric conditions, while climate is long-term patterns over time. | K14: Car | N14: Very Easy | O14: 21-25 students | P14: I did not grow up in the state of Utah | Q14: She is from California in America | R14: California
A15: 46163.753 | B15: 25+ | C15: Male | D15: Married | E15: California | F15: Yes | G15: Sydney Australia | H15: No | I15: Rarely | J15: Weather is short-term atmospheric conditions, while climate is long-term patterns over time. | K15: Car, Walking, Other | N15: Somewhat Easy | O15: 26-30 students | P15: I did not grow up in the state of Utah | Q15: He is from California in America | R15: California
A16: 46163.759 | B16: 25+ | C16: Female | D16: Single | E16: California | F16: No | G16: Na | H16: No | I16: Never | J16: Weather is short-term atmospheric conditions, while climate is long-term patterns over time. | K16: Car, Walking | N16: Somewhat Easy | O16: 31-35 students | P16: I did not grow up in the state of Utah | Q16: She is from California | R16: California
A17: 46163.762 | B17: 25+ | C17: Male | D17: Married | E17: Utah | F17: Yes | G17: Germany, Iraq | H17: No | I17: Often | J17: Not sure. | K17: Car, Walking, Other | N17: Neutral | O17: 21-25 students | P17: Provo | Q17: Provo | R17: Provo
A18: 46163.764 | B18: 21-22 | C18: Male | D18: Single | E18: Nevada | F18: Yes | G18: Japan and Bolivia | H18: Yes | I18: Sometimes | J18: Weather is short-term atmospheric conditions, while climate is long-term patterns over time. | K18: Car, Public transportation (Bus, Train, shuttle, tram, etc.), Walking | N18: Very Easy | O18: 21-25 students | P18: I did not grow up in the state of Utah | Q18: He's from Nevada state | R18: Nevada
A19: 46163.766 | B19: 25+ | C19: Male | D19: Married | E19: Ohio | F19: Yes | G19: Mexico and Nicaragua | H19: No | I19: Sometimes | J19: Weather is short-term atmospheric conditions, while climate is long-term patterns over time. | K19: Car, Walking, Other | N19: Somewhat Easy | O19: 21-25 students | P19: I did not grow up in the state of Utah | Q19: Ohio | R19: Ohio
A20: 46163.779 | B20: 19-20 | C20: Female | D20: Single | E20: Pennsylvania | F20: Yes | G20: N/a | H20: Yes | I20: Sometimes | J20: Weather is short-term atmospheric conditions, while climate is long-term patterns over time. | K20: Car, Walking, Rideshare (Uber/Lyft) | N20: Very Easy | O20: 26-30 students | P20: I did not grow up in the state of Utah | Q20: She's from Pennsylvania | R20: Pennsylvania
A21: 46163.784 | B21: 17-18 | C21: Female | D21: Single | E21: Utah | F21: No | G21: NA | H21: Yes | I21: Sometimes | J21: Weather is short-term atmospheric conditions, while climate is long-term patterns over time. | K21: Car, Public transportation (Bus, Train, shuttle, tram, etc.), Walking | N21: Somewhat Easy | O21: 26-30 students | P21: Davis | Q21: She was from Utah | R21: Davis
A22: 46163.784 | B22: 19-20 | C22: Female | D22: Single | E22: south carolina | F22: No | G22: n/a | H22: Yes | I22: Rarely | J22: Weather is short-term atmospheric conditions, while climate is long-term patterns over time. | K22: Car, Walking, Biking | N22: Somewhat Easy | O22: 21-25 students | P22: I did not grow up in the state of Utah | Q22: She was from the state of South Carolina | R22: South Carolina
A23: 46163.797 | B23: 25+ | C23: Female | D23: Married | E23: Utah | F23: No | G23: N/a | H23: No | I23: Rarely | J23: Weather is short-term atmospheric conditions, while climate is long-term patterns over time. | K23: Car, Walking, Rideshare (Uber/Lyft) | N23: Very Easy | O23: 31-35 students | P23: Salt Lake | Q23: She was from the state of Utah | R23: Salt Lake
... A38: 46163.903 | B38: 25+ | C38: Female | D38: Married | E38: Utah | F38: No | G38: N/A | H38: No | I38: Rarely | J38: Weather is short-term atmospheric conditions, while climate is long-term patterns over time. | K38: Car, Walking | N38: Very Easy | O38: 26-30 students | P38: Davis | Q38: She was from Utah | R38: Davis
A39: 46163.922 | B39: 21-22 | D39: Single | E39: Utah | F39: Yes | G39: Brazil | H39: Yes | I39: Sometimes | J39: Weather is short-term atmospheric conditions, while climate is long-term patterns over time. | K39: Car, Walking, Ridable (electric scooter, skateboard, etc.) | N39: Somewhat Easy | O39: 26-30 students | P39: American Fork | Q39: This person grew up in AF, despite temporarily living in Brazil | R39: American Fork
A40: 46163.929 | B40: 25+ | C40: Female | D40: Single | E40: California | F40: No | G40: None | H40: No | I40: Sometimes | J40: Weather only refers to temperature, while climate only refers to storms. | K40: Car | N40: Very Easy | O40: 26-30 students | P40: I did not grow up in the state of Utah | Q40: This lady is from California | R40: California
A41: 46163.946 | B41: 21-22 | C41: Female | D41: Single | E41: WA | F41: No | G41: Na | H41: Yes | I41: Sometimes | J41: Weather is short-term atmospheric conditions, while climate is long-term patterns over time. | K41: Car, Public transportation (Bus, Train, shuttle, tram, etc.), Walking | N41: Very Easy | O41: 21-25 students | P41: I did not grow up in the state of Utah | Q41: She is from Washington state and not Washington County | R41: Washington State
A42: 46163.951 | B42: 25+ | C42: Male | D42: Married | E42: California | F42: Yes | G42: Taiwan | H42: No | I42: Rarely | J42: Weather is short-term atmospheric conditions, while climate is long-term patterns over time. | K42: Car, Walking, Biking | N42: Very Easy | O42: 26-30 students | P42: I did not grow up in the state of Utah | Q42: He is from California, despite also putting Taiwan | R42: California
A43: 46163.952 | B43: 25+ | C43: Male | D43: Married | E43: Utah | F43: Yes | G43: Afghanistan and Iraq | H43: No | I43: Rarely | J43: Weather is short-term atmospheric conditions, while climate is long-term patterns over time. | K43: Car, Walking, Rideshare (Uber/Lyft) | N43: Very Easy | O43: 31-35 students | P43: Salt Lake | Q43: This guy's from Utah | R43: Salt Lake
A44: 46164.037 | B44: 19-20 | C44: Female | D44: Single | E44: Utah | F44: Yes | G44: n/a | H44: Yes | I44: Rarely | J44: Weather is short-term atmospheric conditions, while climate is long-term patterns over time. | K44: Car, Public transportation (Bus, Train, shuttle, tram, etc.), Walking | N44: Very Easy | O44: 31-35 students | P44: Orem | Q44: This lady is from Orem, Utah | R44: Orem
A45: 46164.077 | B45: 25+ | C45: Male | D45: Married | E45: California | F45: Yes | G45: Iraq and Spain | H45: Yes | I45: Often | J45: Weather is short-term atmospheric conditions, while climate is long-term patterns over time. | K45: Car, Walking, Biking | N45: Neutral | O45: 31-35 students | P45: Washington | Q45: He is from Utah, despite also putting California and Spain | R45: Washington
A46: 46164.188 | B46: 25+ | C46: Male | D46: Married | E46: Utah | F46: Yes | G46: Mexico, Iraq. Afghanistan | H46: No | I46: Rarely | J46: Weather is short-term atmospheric conditions, while climate is long-term patterns over time. | K46: Car, Walking | N46: Very Easy | O46: 21-25 students | P46: Salt Lake | Q46: We will use "Salt Lake" and not "Iraq" | R46: Salt Lake
A47: 46164.233 | B47: 21-22 | C47: Male | D47: Single | E47: I'm from Brazil | F47: Yes | G47: Portugal | H47: Yes | I47: Sometimes | J47: Weather is short-term atmospheric conditions, while climate is long-term patterns over time. | K47: Car, Public transportation (Bus, Train, shuttle, tram, etc.), Walking | N47: Very Easy | O47: 41-45 students | P47: I did not grow up in the state of Utah | Q47: Brazil and Portugal | R47: Foreign Country
A48: 46164.289 | B48: 25+ | C48: Female | D48: Single | E48: California | F48: Yes | G48: N/A | H48: No | I48: Rarely | J48: Weather is short-term atmospheric conditions, while climate is long-term patterns over time. | K48: Car | N48: Very Easy | O48: 16-20 students | P48: I did not grow up in the state of Utah | Q48: This lady was from California | R48: California
A49: 46164.331 | B49: 19-20 | C49: Female | D49: Single | E49: New York | F49: No | G49: N/A | H49: Yes | I49: Often | J49: Weather is short-term atmospheric conditions, while climate is long-term patterns over time. | K49: Car, Public transportation (Bus, Train, shuttle, tram, etc.), Walking | N49: Very Easy | O49: 26-30 students | P49: I did not grow up in the state of Utah | Q49: This lady was from New York | R49: New York
A50: 46164.351 | B50: 25+ | C50: Male | D50: Married | E50: California | F50: No | G50: N/A | H50: No | I50: Rarely | J50: Weather is short-term atmospheric conditions, while climate is long-term patterns over time. | K50: Car, Walking | N50: Somewhat Easy | O50: 26-30 students | P50: I did not grow up in the state of Utah | Q50: This guy was from California | R50: California
A51: 46164.357 | B51: 25+ | C51: Male | D51: Married | E51: Utah | F51: Yes | G51: Brazil, Iraq, Germany, Kosovo | H51: No | I51: Sometimes | J51: Weather is short-term atmospheric conditions, while climate is long-term patterns over time. | K51: Car, Walking | N51: Very Easy | O51: 31-35 students | P51: American Fork | Q51: We will use "Utah" and not "Iraq" | R51: American Fork
... A106: 46170.779 | B106: 25+ | C106: Male | D106: Married | E106: Utah | F106: Yes | G106: Portugal, Iraq, Camaroon | H106: No | I106: Rarely | J106: Weather is short-term atmospheric conditions, while climate is long-term patterns over time. | K106: Car, Walking, Rideshare (Uber/Lyft) | N106: Very Easy | O106: 31-35 students | P106: Salt Lake | Q106: We will use "Utah" instead of "Iraq" | R106: Salt Lake

Sheet Sheet2
A1: American Fork | B1: =1 -> 1 | C1: =_xlfn.CONCAT("if(d1=",$Q$16,A1,$Q$16,",",B1,",") -> if(d1="American Fork",1, | D1: =Sheet1!P2 -> Davis | E1: =IF(D1="American Fork",1,IF(D1="Beaver",2,IF(D1="Box Elder",3,IF(D1="Cache",4,IF(D1="Carbon",5,IF(D1="Daggett",6,IF(D1="Davis",7,IF(D1="Duchesne",8,IF(D1="Eagle Mountain",9,IF(D1="Emery",10,IF(D1="Garfield",11,IF(D1="Grand",12,IF(D1="Herriman",13,IF(D1="I did not grow up in the state of Utah",14,IF(D1="Iron",15,IF(D1="Juab",16,IF(D1="Kane",17,IF(D1="Layton",18,IF(D1="Lindon",19,IF(D1="Millard",20,IF(D1="Morgan",21,IF(D1="Ogden",22,IF(D1="Orem",23,IF(D1="Payson",24,IF(D1="Piute",25,IF(D1="Pleasant Grove",26,IF(D1="Provo",27,IF(D1="Rich",28,IF(D1="Salt Lake",29,IF(D1="San Juan",30,IF(D1="Sanpete",31,IF(D1="Saratoga Springs",32,IF(D1="Sevier",33,IF(D1="Springville",34,IF(D1="Summit",35,IF(D1="Tooele",36,IF(D1="Uintah",37,IF(D1="Wasatch",38,IF(D1="Washington",39,IF(D1="Wayne",40,41)))))))))))))))))))))))))))))))))))))))) -> 7 | G1: =Sheet1!O2 -> 26-30 students | J1: 5 | K1: =_xlfn.CONCAT(J1-4,"-",J1," students") -> 1-5 students | U1: County | Y1: County Code | AA1: Class Size | AC1: Class Size Code | AE1: Place of Origin | AI1: Place of Origin Summary | AL1: Place of Origin Code | AN1: Codes for Places of Origin
A2: Beaver | B2: =1+B1 -> 2 | C2: =_xlfn.CONCAT(C1,"if(d1=",$Q$16,A2,$Q$16,",",B2,",") -> if(d1="American Fork",1,if(d1="Beaver",2, | D2: =Sheet1!P3 -> Sanpete | E2: =IF(D2="American Fork",1,IF(D2="Beaver",2,IF(D2="Box Elder",3,IF(D2="Cache",4,IF(D2="Carbon",5,IF(D2="Daggett",6,IF(D2="Davis",7,IF(D2="Duchesne",8,IF(D2="Eagle Mountain",9,IF(D2="Emery",10,IF(D2="Garfield",11,IF(D2="Grand",12,IF(D2="Herriman",13,IF(D2="I did not grow up in the state of Utah",14,IF(D2="Iron",15,IF(D2="Juab",16,IF(D2="Kane",17,IF(D2="Layton",18,IF(D2="Lindon",19,IF(D2="Millard",20,IF(D2="Morgan",21,IF(D2="Ogden",22,IF(D2="Orem",23,IF(D2="Payson",24,IF(D2="Piute",25,IF(D2="Pleasant Grove",26,IF(D2="Provo",27,IF(D2="Rich",28,IF(D2="Salt Lake",29,IF(D2="San Juan",30,IF(D2="Sanpete",31,IF(D2="Saratoga Springs",32,IF(D2="Sevier",33,IF(D2="Springville",34,IF(D2="Summit",35,IF(D2="Tooele",36,IF(D2="Uintah",37,IF(D2="Wasatch",38,IF(D2="Washington",39,IF(D2="Wayne",40,41)))))))))))))))))))))))))))))))))))))))) -> 31 | G2: =Sheet1!O3 -> 26-30 students | J2: =J1+5 -> 10 | K2: =_xlfn.CONCAT(J2-4,"-",J2," students") -> 6-10 students | Q2: =_xlfn.CONCAT("if(ai2=",$Q$16,AO2,$Q$16,",",AN2,",",Q3,")") -> if(ai2="North East Utah County",1,if(ai2="South East Utah County",2,if(ai2="Western Utah County",3,if(ai2="Eastern Utah",4,if(ai2="Midwest Utah",5,if(ai2="Western Utah",6,if(ai2="North",7,if(ai2="South",8,if(ai2="East",9,if(ai2="West",10,if(ai2="Not From America",11,0))))))))))) | U2: =D1 -> Davis | Y2: =E1 -> 7 | AA2: =G1 -> 26-30 students | AC2: =_xlfn.FLOOR.MATH(J25/5+0.2) -> 6 | AE2: =Sheet1!R2 -> Davis | AI2: =IF(AE2="Weber","Eastern Utah",IF(AE2="Wayne","Eastern Utah",IF(AE2="Washington","Western Utah",IF(AE2="Wasatch","Eastern Utah",IF(AE2="Uintah","Eastern Utah",IF(AE2="Tooele","Midwest Utah",IF(AE2="Summit","Eastern Utah",IF(AE2="Springville","South East Utah County",IF(AE2="Sevier","Midwest Utah",IF(AE2="Saratoga Springs","North East Utah County",IF(AE2="Sanpete","Midwest Utah",IF(AE2="San Juan","Midwest Utah",IF(AE2="Salt Lake","Eastern Utah",IF(AE2="Rich","Eastern Utah",IF(AE2="Provo","Western Utah County",IF(AE2="Pleasant Grove","South East Utah County",IF(AE2="Piute","Midwest Utah",IF(AE2="Payson","South East Utah County",IF(AE2="Orem","South East Utah County",IF(AE2="Ogden","Western Utah County",IF(AE2="Morgan","Eastern Utah",IF(AE2="Millard","Midwest Utah",IF(AE2="Lindon","South East Utah County",IF(AE2="Layton","North East Utah County",IF(AE2="Kane","Western Utah",IF(AE2="Juab","Midwest Utah",IF(AE2="Iron","Western Utah",IF(AE2="I did not grow up in the state of Utah","South",IF(AE2="Herriman","Western Utah County",IF(AE2="Grand","Eastern Utah",IF(AE2="Garfield","Midwest Utah",IF(AE2="Emery","Eastern Utah",IF(AE2="Eagle Mountain","Western Utah County",IF(AE2="Duchesne","Eastern Utah",IF(AE2="Davis","Eastern Utah",IF(AE2="Daggett","Eastern Utah",IF(AE2="Carbon","Eastern Utah",IF(AE2="Cache","Midwest Utah",IF(AE2="Box Elder","Midwest Utah",IF(AE2="Beaver","Western Utah",IF(AE2="American Fork","North East Utah County",IF(AE2="Washington State","West",IF(AE2="Virginia","South",IF(AE2="Texas","South",IF(AE2="South Carolina","South",IF(AE2="Phoenix, Arizona","North",IF(AE2="Pennsylvania","East",IF(AE2="Ohio","North",IF(AE2="North Carolina","South",IF(AE2="New York","East",IF(AE2="New Jersey","East",IF(AE2="Nevada","West",IF(AE2="Massachusetts","East",IF(AE2="Lake Havasu, Arizona","West",IF(AE2="Iowa","North",IF(AE2="Idaho","West",IF(AE2="Hawaii","West",IF(AE2="Gilbert, Arizona","South",IF(AE2="Foreign Country","Not From America",IF(AE2="California","West",IF(AE2="Arkansas","North",IF(AE2="Alaska","West","x")))))))))))))))))))))))))))))))))))))))))))))))))))))))))))))) -> Eastern Utah | AL2: =IF(AI2="North East Utah County",1,IF(AI2="South East Utah County",2,IF(AI2="Western Utah County",3,IF(AI2="Eastern Utah",4,IF(AI2="Midwest Utah",5,IF(AI2="Western Utah",6,IF(AI2="North",7,IF(AI2="South",8,IF(AI2="East",9,IF(AI2="West",10,IF(AI2="Not From America",11,0))))))))))) -> 4 | AN2: 1 | AO2: North East Utah County
A3: Box Elder | B3: =1+B2 -> 3 | C3: =_xlfn.CONCAT(C2,"if(d1=",$Q$16,A3,$Q$16,",",B3,",") -> if(d1="American Fork",1,if(d1="Beaver",2,if(d1="Box Elder",3, | D3: =Sheet1!P4 -> I did not grow up in the state of Utah | E3: =IF(D3="American Fork",1,IF(D3="Beaver",2,IF(D3="Box Elder",3,IF(D3="Cache",4,IF(D3="Carbon",5,IF(D3="Daggett",6,IF(D3="Davis",7,IF(D3="Duchesne",8,IF(D3="Eagle Mountain",9,IF(D3="Emery",10,IF(D3="Garfield",11,IF(D3="Grand",12,IF(D3="Herriman",13,IF(D3="I did not grow up in the state of Utah",14,IF(D3="Iron",15,IF(D3="Juab",16,IF(D3="Kane",17,IF(D3="Layton",18,IF(D3="Lindon",19,IF(D3="Millard",20,IF(D3="Morgan",21,IF(D3="Ogden",22,IF(D3="Orem",23,IF(D3="Payson",24,IF(D3="Piute",25,IF(D3="Pleasant Grove",26,IF(D3="Provo",27,IF(D3="Rich",28,IF(D3="Salt Lake",29,IF(D3="San Juan",30,IF(D3="Sanpete",31,IF(D3="Saratoga Springs",32,IF(D3="Sevier",33,IF(D3="Springville",34,IF(D3="Summit",35,IF(D3="Tooele",36,IF(D3="Uintah",37,IF(D3="Wasatch",38,IF(D3="Washington",39,IF(D3="Wayne",40,41)))))))))))))))))))))))))))))))))))))))) -> 14 | G3: =Sheet1!O4 -> 26-30 students | J3: =J2+5 -> 15 | K3: =_xlfn.CONCAT(J3-4,"-",J3," students") -> 11-15 students | Q3: =_xlfn.CONCAT("if(ai2=",$Q$16,AO3,$Q$16,",",AN3,",",Q4,")") -> if(ai2="South East Utah County",2,if(ai2="Western Utah County",3,if(ai2="Eastern Utah",4,if(ai2="Midwest Utah",5,if(ai2="Western Utah",6,if(ai2="North",7,if(ai2="South",8,if(ai2="East",9,if(ai2="West",10,if(ai2="Not From America",11,0)))))))))) | U3: =D2 -> Sanpete | Y3: =E2 -> 31 | AA3: =G2 -> 26-30 students | AC3: =_xlfn.FLOOR.MATH(J26/5+0.2) -> 6 | AE3: =Sheet1!R3 -> Sanpete | AI3: =IF(AE3="Weber","Eastern Utah",IF(AE3="Wayne","Eastern Utah",IF(AE3="Washington","Western Utah",IF(AE3="Wasatch","Eastern Utah",IF(AE3="Uintah","Eastern Utah",IF(AE3="Tooele","Midwest Utah",IF(AE3="Summit","Eastern Utah",IF(AE3="Springville","South East Utah County",IF(AE3="Sevier","Midwest Utah",IF(AE3="Saratoga Springs","North East Utah County",IF(AE3="Sanpete","Midwest Utah",IF(AE3="San Juan","Midwest Utah",IF(AE3="Salt Lake","Eastern Utah",IF(AE3="Rich","Eastern Utah",IF(AE3="Provo","Western Utah County",IF(AE3="Pleasant Grove","South East Utah County",IF(AE3="Piute","Midwest Utah",IF(AE3="Payson","South East Utah County",IF(AE3="Orem","South East Utah County",IF(AE3="Ogden","Western Utah County",IF(AE3="Morgan","Eastern Utah",IF(AE3="Millard","Midwest Utah",IF(AE3="Lindon","South East Utah County",IF(AE3="Layton","North East Utah County",IF(AE3="Kane","Western Utah",IF(AE3="Juab","Midwest Utah",IF(AE3="Iron","Western Utah",IF(AE3="I did not grow up in the state of Utah","South",IF(AE3="Herriman","Western Utah County",IF(AE3="Grand","Eastern Utah",IF(AE3="Garfield","Midwest Utah",IF(AE3="Emery","Eastern Utah",IF(AE3="Eagle Mountain","Western Utah County",IF(AE3="Duchesne","Eastern Utah",IF(AE3="Davis","Eastern Utah",IF(AE3="Daggett","Eastern Utah",IF(AE3="Carbon","Eastern Utah",IF(AE3="Cache","Midwest Utah",IF(AE3="Box Elder","Midwest Utah",IF(AE3="Beaver","Western Utah",IF(AE3="American Fork","North East Utah County",IF(AE3="Washington State","West",IF(AE3="Virginia","South",IF(AE3="Texas","South",IF(AE3="South Carolina","South",IF(AE3="Phoenix, Arizona","North",IF(AE3="Pennsylvania","East",IF(AE3="Ohio","North",IF(AE3="North Carolina","South",IF(AE3="New York","East",IF(AE3="New Jersey","East",IF(AE3="Nevada","West",IF(AE3="Massachusetts","East",IF(AE3="Lake Havasu, Arizona","West",IF(AE3="Iowa","North",IF(AE3="Idaho","West",IF(AE3="Hawaii","West",IF(AE3="Gilbert, Arizona","South",IF(AE3="Foreign Country","Not From America",IF(AE3="California","West",IF(AE3="Arkansas","North",IF(AE3="Alaska","West","x")))))))))))))))))))))))))))))))))))))))))))))))))))))))))))))) -> Midwest Utah | AL3: =IF(AI3="North East Utah County",1,IF(AI3="South East Utah County",2,IF(AI3="Western Utah County",3,IF(AI3="Eastern Utah",4,IF(AI3="Midwest Utah",5,IF(AI3="Western Utah",6,IF(AI3="North",7,IF(AI3="South",8,IF(AI3="East",9,IF(AI3="West",10,IF(AI3="Not From America",11,0))))))))))) -> 5 | AN3: =1+AN2 -> 2 | AO3: South East Utah County
A4: Cache | B4: =1+B3 -> 4 | C4: =_xlfn.CONCAT(C3,"if(d1=",$Q$16,A4,$Q$16,",",B4,",") -> if(d1="American Fork",1,if(d1="Beaver",2,if(d1="Box Elder",3,if(d1="Cache",4, | D4: =Sheet1!P5 -> I did not grow up in the state of Utah | E4: =IF(D4="American Fork",1,IF(D4="Beaver",2,IF(D4="Box Elder",3,IF(D4="Cache",4,IF(D4="Carbon",5,IF(D4="Daggett",6,IF(D4="Davis",7,IF(D4="Duchesne",8,IF(D4="Eagle Mountain",9,IF(D4="Emery",10,IF(D4="Garfield",11,IF(D4="Grand",12,IF(D4="Herriman",13,IF(D4="I did not grow up in the state of Utah",14,IF(D4="Iron",15,IF(D4="Juab",16,IF(D4="Kane",17,IF(D4="Layton",18,IF(D4="Lindon",19,IF(D4="Millard",20,IF(D4="Morgan",21,IF(D4="Ogden",22,IF(D4="Orem",23,IF(D4="Payson",24,IF(D4="Piute",25,IF(D4="Pleasant Grove",26,IF(D4="Provo",27,IF(D4="Rich",28,IF(D4="Salt Lake",29,IF(D4="San Juan",30,IF(D4="Sanpete",31,IF(D4="Saratoga Springs",32,IF(D4="Sevier",33,IF(D4="Springville",34,IF(D4="Summit",35,IF(D4="Tooele",36,IF(D4="Uintah",37,IF(D4="Wasatch",38,IF(D4="Washington",39,IF(D4="Wayne",40,41)))))))))))))))))))))))))))))))))))))))) -> 14 | G4: =Sheet1!O5 -> 31-35 students | J4: =J3+5 -> 20 | K4: =_xlfn.CONCAT(J4-4,"-",J4," students") -> 16-20 students | Q4: =_xlfn.CONCAT("if(ai2=",$Q$16,AO4,$Q$16,",",AN4,",",Q5,")") -> if(ai2="Western Utah County",3,if(ai2="Eastern Utah",4,if(ai2="Midwest Utah",5,if(ai2="Western Utah",6,if(ai2="North",7,if(ai2="South",8,if(ai2="East",9,if(ai2="West",10,if(ai2="Not From America",11,0))))))))) | U4: =D3 -> I did not grow up in the state of Utah | Y4: =E3 -> 14 | AA4: =G3 -> 26-30 students | AC4: =_xlfn.FLOOR.MATH(J27/5+0.2) -> 6 | AE4: =Sheet1!R4 -> California | AI4: =IF(AE4="Weber","Eastern Utah",IF(AE4="Wayne","Eastern Utah",IF(AE4="Washington","Western Utah",IF(AE4="Wasatch","Eastern Utah",IF(AE4="Uintah","Eastern Utah",IF(AE4="Tooele","Midwest Utah",IF(AE4="Summit","Eastern Utah",IF(AE4="Springville","South East Utah County",IF(AE4="Sevier","Midwest Utah",IF(AE4="Saratoga Springs","North East Utah County",IF(AE4="Sanpete","Midwest Utah",IF(AE4="San Juan","Midwest Utah",IF(AE4="Salt Lake","Eastern Utah",IF(AE4="Rich","Eastern Utah",IF(AE4="Provo","Western Utah County",IF(AE4="Pleasant Grove","South East Utah County",IF(AE4="Piute","Midwest Utah",IF(AE4="Payson","South East Utah County",IF(AE4="Orem","South East Utah County",IF(AE4="Ogden","Western Utah County",IF(AE4="Morgan","Eastern Utah",IF(AE4="Millard","Midwest Utah",IF(AE4="Lindon","South East Utah County",IF(AE4="Layton","North East Utah County",IF(AE4="Kane","Western Utah",IF(AE4="Juab","Midwest Utah",IF(AE4="Iron","Western Utah",IF(AE4="I did not grow up in the state of Utah","South",IF(AE4="Herriman","Western Utah County",IF(AE4="Grand","Eastern Utah",IF(AE4="Garfield","Midwest Utah",IF(AE4="Emery","Eastern Utah",IF(AE4="Eagle Mountain","Western Utah County",IF(AE4="Duchesne","Eastern Utah",IF(AE4="Davis","Eastern Utah",IF(AE4="Daggett","Eastern Utah",IF(AE4="Carbon","Eastern Utah",IF(AE4="Cache","Midwest Utah",IF(AE4="Box Elder","Midwest Utah",IF(AE4="Beaver","Western Utah",IF(AE4="American Fork","North East Utah County",IF(AE4="Washington State","West",IF(AE4="Virginia","South",IF(AE4="Texas","South",IF(AE4="South Carolina","South",IF(AE4="Phoenix, Arizona","North",IF(AE4="Pennsylvania","East",IF(AE4="Ohio","North",IF(AE4="North Carolina","South",IF(AE4="New York","East",IF(AE4="New Jersey","East",IF(AE4="Nevada","West",IF(AE4="Massachusetts","East",IF(AE4="Lake Havasu, Arizona","West",IF(AE4="Iowa","North",IF(AE4="Idaho","West",IF(AE4="Hawaii","West",IF(AE4="Gilbert, Arizona","South",IF(AE4="Foreign Country","Not From America",IF(AE4="California","West",IF(AE4="Arkansas","North",IF(AE4="Alaska","West","x")))))))))))))))))))))))))))))))))))))))))))))))))))))))))))))) -> West | AL4: =IF(AI4="North East Utah County",1,IF(AI4="South East Utah County",2,IF(AI4="Western Utah County",3,IF(AI4="Eastern Utah",4,IF(AI4="Midwest Utah",5,IF(AI4="Western Utah",6,IF(AI4="North",7,IF(AI4="South",8,IF(AI4="East",9,IF(AI4="West",10,IF(AI4="Not From America",11,0))))))))))) -> 10 | AN4: =1+AN3 -> 3 | AO4: Western Utah County
A5: Carbon | B5: =1+B4 -> 5 | C5: =_xlfn.CONCAT(C4,"if(d1=",$Q$16,A5,$Q$16,",",B5,",") -> if(d1="American Fork",1,if(d1="Beaver",2,if(d1="Box Elder",3,if(d1="Cache",4,if(d1="Carbon",5, | D5: =Sheet1!P6 -> I did not grow up in the state of Utah | E5: =IF(D5="American Fork",1,IF(D5="Beaver",2,IF(D5="Box Elder",3,IF(D5="Cache",4,IF(D5="Carbon",5,IF(D5="Daggett",6,IF(D5="Davis",7,IF(D5="Duchesne",8,IF(D5="Eagle Mountain",9,IF(D5="Emery",10,IF(D5="Garfield",11,IF(D5="Grand",12,IF(D5="Herriman",13,IF(D5="I did not grow up in the state of Utah",14,IF(D5="Iron",15,IF(D5="Juab",16,IF(D5="Kane",17,IF(D5="Layton",18,IF(D5="Lindon",19,IF(D5="Millard",20,IF(D5="Morgan",21,IF(D5="Ogden",22,IF(D5="Orem",23,IF(D5="Payson",24,IF(D5="Piute",25,IF(D5="Pleasant Grove",26,IF(D5="Provo",27,IF(D5="Rich",28,IF(D5="Salt Lake",29,IF(D5="San Juan",30,IF(D5="Sanpete",31,IF(D5="Saratoga Springs",32,IF(D5="Sevier",33,IF(D5="Springville",34,IF(D5="Summit",35,IF(D5="Tooele",36,IF(D5="Uintah",37,IF(D5="Wasatch",38,IF(D5="Washington",39,IF(D5="Wayne",40,41)))))))))))))))))))))))))))))))))))))))) -> 14 | G5: =Sheet1!O6 -> 21-25 students | J5: =J4+5 -> 25 | K5: =_xlfn.CONCAT(J5-4,"-",J5," students") -> 21-25 students | Q5: =_xlfn.CONCAT("if(ai2=",$Q$16,AO5,$Q$16,",",AN5,",",Q6,")") -> if(ai2="Eastern Utah",4,if(ai2="Midwest Utah",5,if(ai2="Western Utah",6,if(ai2="North",7,if(ai2="South",8,if(ai2="East",9,if(ai2="West",10,if(ai2="Not From America",11,0)))))))) | U5: =D4 -> I did not grow up in the state of Utah | Y5: =E4 -> 14 | AA5: =G4 -> 31-35 students | AC5: =_xlfn.FLOOR.MATH(J28/5+0.2) -> 7 | AE5: =Sheet1!R5 -> California | AI5: =IF(AE5="Weber","Eastern Utah",IF(AE5="Wayne","Eastern Utah",IF(AE5="Washington","Western Utah",IF(AE5="Wasatch","Eastern Utah",IF(AE5="Uintah","Eastern Utah",IF(AE5="Tooele","Midwest Utah",IF(AE5="Summit","Eastern Utah",IF(AE5="Springville","South East Utah County",IF(AE5="Sevier","Midwest Utah",IF(AE5="Saratoga Springs","North East Utah County",IF(AE5="Sanpete","Midwest Utah",IF(AE5="San Juan","Midwest Utah",IF(AE5="Salt Lake","Eastern Utah",IF(AE5="Rich","Eastern Utah",IF(AE5="Provo","Western Utah County",IF(AE5="Pleasant Grove","South East Utah County",IF(AE5="Piute","Midwest Utah",IF(AE5="Payson","South East Utah County",IF(AE5="Orem","South East Utah County",IF(AE5="Ogden","Western Utah County",IF(AE5="Morgan","Eastern Utah",IF(AE5="Millard","Midwest Utah",IF(AE5="Lindon","South East Utah County",IF(AE5="Layton","North East Utah County",IF(AE5="Kane","Western Utah",IF(AE5="Juab","Midwest Utah",IF(AE5="Iron","Western Utah",IF(AE5="I did not grow up in the state of Utah","South",IF(AE5="Herriman","Western Utah County",IF(AE5="Grand","Eastern Utah",IF(AE5="Garfield","Midwest Utah",IF(AE5="Emery","Eastern Utah",IF(AE5="Eagle Mountain","Western Utah County",IF(AE5="Duchesne","Eastern Utah",IF(AE5="Davis","Eastern Utah",IF(AE5="Daggett","Eastern Utah",IF(AE5="Carbon","Eastern Utah",IF(AE5="Cache","Midwest Utah",IF(AE5="Box Elder","Midwest Utah",IF(AE5="Beaver","Western Utah",IF(AE5="American Fork","North East Utah County",IF(AE5="Washington State","West",IF(AE5="Virginia","South",IF(AE5="Texas","South",IF(AE5="South Carolina","South",IF(AE5="Phoenix, Arizona","North",IF(AE5="Pennsylvania","East",IF(AE5="Ohio","North",IF(AE5="North Carolina","South",IF(AE5="New York","East",IF(AE5="New Jersey","East",IF(AE5="Nevada","West",IF(AE5="Massachusetts","East",IF(AE5="Lake Havasu, Arizona","West",IF(AE5="Iowa","North",IF(AE5="Idaho","West",IF(AE5="Hawaii","West",IF(AE5="Gilbert, Arizona","South",IF(AE5="Foreign Country","Not From America",IF(AE5="California","West",IF(AE5="Arkansas","North",IF(AE5="Alaska","West","x")))))))))))))))))))))))))))))))))))))))))))))))))))))))))))))) -> West | AL5: =IF(AI5="North East Utah County",1,IF(AI5="South East Utah County",2,IF(AI5="Western Utah County",3,IF(AI5="Eastern Utah",4,IF(AI5="Midwest Utah",5,IF(AI5="Western Utah",6,IF(AI5="North",7,IF(AI5="South",8,IF(AI5="East",9,IF(AI5="West",10,IF(AI5="Not From America",11,0))))))))))) -> 10 | AN5: =1+AN4 -> 4 | AO5: Eastern Utah
A6: Daggett | B6: =1+B5 -> 6 | C6: =_xlfn.CONCAT(C5,"if(d1=",$Q$16,A6,$Q$16,",",B6,",") -> if(d1="American Fork",1,if(d1="Beaver",2,if(d1="Box Elder",3,if(d1="Cache",4,if(d1="Carbon",5,if(d1="Daggett",6, | D6: =Sheet1!P7 -> I did not grow up in the state of Utah | E6: =IF(D6="American Fork",1,IF(D6="Beaver",2,IF(D6="Box Elder",3,IF(D6="Cache",4,IF(D6="Carbon",5,IF(D6="Daggett",6,IF(D6="Davis",7,IF(D6="Duchesne",8,IF(D6="Eagle Mountain",9,IF(D6="Emery",10,IF(D6="Garfield",11,IF(D6="Grand",12,IF(D6="Herriman",13,IF(D6="I did not grow up in the state of Utah",14,IF(D6="Iron",15,IF(D6="Juab",16,IF(D6="Kane",17,IF(D6="Layton",18,IF(D6="Lindon",19,IF(D6="Millard",20,IF(D6="Morgan",21,IF(D6="Ogden",22,IF(D6="Orem",23,IF(D6="Payson",24,IF(D6="Piute",25,IF(D6="Pleasant Grove",26,IF(D6="Provo",27,IF(D6="Rich",28,IF(D6="Salt Lake",29,IF(D6="San Juan",30,IF(D6="Sanpete",31,IF(D6="Saratoga Springs",32,IF(D6="Sevier",33,IF(D6="Springville",34,IF(D6="Summit",35,IF(D6="Tooele",36,IF(D6="Uintah",37,IF(D6="Wasatch",38,IF(D6="Washington",39,IF(D6="Wayne",40,41)))))))))))))))))))))))))))))))))))))))) -> 14 | G6: =Sheet1!O7 -> 21-25 students | J6: =J5+5 -> 30 | K6: =_xlfn.CONCAT(J6-4,"-",J6," students") -> 26-30 students | Q6: =_xlfn.CONCAT("if(ai2=",$Q$16,AO6,$Q$16,",",AN6,",",Q7,")") -> if(ai2="Midwest Utah",5,if(ai2="Western Utah",6,if(ai2="North",7,if(ai2="South",8,if(ai2="East",9,if(ai2="West",10,if(ai2="Not From America",11,0))))))) | U6: =D5 -> I did not grow up in the state of Utah | Y6: =E5 -> 14 | AA6: =G5 -> 21-25 students | AC6: =_xlfn.FLOOR.MATH(J29/5+0.2) -> 5 | AE6: =Sheet1!R6 -> California | AI6: =IF(AE6="Weber","Eastern Utah",IF(AE6="Wayne","Eastern Utah",IF(AE6="Washington","Western Utah",IF(AE6="Wasatch","Eastern Utah",IF(AE6="Uintah","Eastern Utah",IF(AE6="Tooele","Midwest Utah",IF(AE6="Summit","Eastern Utah",IF(AE6="Springville","South East Utah County",IF(AE6="Sevier","Midwest Utah",IF(AE6="Saratoga Springs","North East Utah County",IF(AE6="Sanpete","Midwest Utah",IF(AE6="San Juan","Midwest Utah",IF(AE6="Salt Lake","Eastern Utah",IF(AE6="Rich","Eastern Utah",IF(AE6="Provo","Western Utah County",IF(AE6="Pleasant Grove","South East Utah County",IF(AE6="Piute","Midwest Utah",IF(AE6="Payson","South East Utah County",IF(AE6="Orem","South East Utah County",IF(AE6="Ogden","Western Utah County",IF(AE6="Morgan","Eastern Utah",IF(AE6="Millard","Midwest Utah",IF(AE6="Lindon","South East Utah County",IF(AE6="Layton","North East Utah County",IF(AE6="Kane","Western Utah",IF(AE6="Juab","Midwest Utah",IF(AE6="Iron","Western Utah",IF(AE6="I did not grow up in the state of Utah","South",IF(AE6="Herriman","Western Utah County",IF(AE6="Grand","Eastern Utah",IF(AE6="Garfield","Midwest Utah",IF(AE6="Emery","Eastern Utah",IF(AE6="Eagle Mountain","Western Utah County",IF(AE6="Duchesne","Eastern Utah",IF(AE6="Davis","Eastern Utah",IF(AE6="Daggett","Eastern Utah",IF(AE6="Carbon","Eastern Utah",IF(AE6="Cache","Midwest Utah",IF(AE6="Box Elder","Midwest Utah",IF(AE6="Beaver","Western Utah",IF(AE6="American Fork","North East Utah County",IF(AE6="Washington State","West",IF(AE6="Virginia","South",IF(AE6="Texas","South",IF(AE6="South Carolina","South",IF(AE6="Phoenix, Arizona","North",IF(AE6="Pennsylvania","East",IF(AE6="Ohio","North",IF(AE6="North Carolina","South",IF(AE6="New York","East",IF(AE6="New Jersey","East",IF(AE6="Nevada","West",IF(AE6="Massachusetts","East",IF(AE6="Lake Havasu, Arizona","West",IF(AE6="Iowa","North",IF(AE6="Idaho","West",IF(AE6="Hawaii","West",IF(AE6="Gilbert, Arizona","South",IF(AE6="Foreign Country","Not From America",IF(AE6="California","West",IF(AE6="Arkansas","North",IF(AE6="Alaska","West","x")))))))))))))))))))))))))))))))))))))))))))))))))))))))))))))) -> West | AL6: =IF(AI6="North East Utah County",1,IF(AI6="South East Utah County",2,IF(AI6="Western Utah County",3,IF(AI6="Eastern Utah",4,IF(AI6="Midwest Utah",5,IF(AI6="Western Utah",6,IF(AI6="North",7,IF(AI6="South",8,IF(AI6="East",9,IF(AI6="West",10,IF(AI6="Not From America",11,0))))))))))) -> 10 | AN6: =1+AN5 -> 5 | AO6: Midwest Utah
A7: Davis | B7: =1+B6 -> 7 | C7: =_xlfn.CONCAT(C6,"if(d1=",$Q$16,A7,$Q$16,",",B7,",") -> if(d1="American Fork",1,if(d1="Beaver",2,if(d1="Box Elder",3,if(d1="Cache",4,if(d1="Carbon",5,if(d1="Daggett",6,if(d1="Davis",7, | D7: =Sheet1!P8 -> I did not grow up in the state of Utah | E7: =IF(D7="American Fork",1,IF(D7="Beaver",2,IF(D7="Box Elder",3,IF(D7="Cache",4,IF(D7="Carbon",5,IF(D7="Daggett",6,IF(D7="Davis",7,IF(D7="Duchesne",8,IF(D7="Eagle Mountain",9,IF(D7="Emery",10,IF(D7="Garfield",11,IF(D7="Grand",12,IF(D7="Herriman",13,IF(D7="I did not grow up in the state of Utah",14,IF(D7="Iron",15,IF(D7="Juab",16,IF(D7="Kane",17,IF(D7="Layton",18,IF(D7="Lindon",19,IF(D7="Millard",20,IF(D7="Morgan",21,IF(D7="Ogden",22,IF(D7="Orem",23,IF(D7="Payson",24,IF(D7="Piute",25,IF(D7="Pleasant Grove",26,IF(D7="Provo",27,IF(D7="Rich",28,IF(D7="Salt Lake",29,IF(D7="San Juan",30,IF(D7="Sanpete",31,IF(D7="Saratoga Springs",32,IF(D7="Sevier",33,IF(D7="Springville",34,IF(D7="Summit",35,IF(D7="Tooele",36,IF(D7="Uintah",37,IF(D7="Wasatch",38,IF(D7="Washington",39,IF(D7="Wayne",40,41)))))))))))))))))))))))))))))))))))))))) -> 14 | G7: =Sheet1!O8 -> 26-30 students | J7: =J6+5 -> 35 | K7: =_xlfn.CONCAT(J7-4,"-",J7," students") -> 31-35 students | Q7: =_xlfn.CONCAT("if(ai2=",$Q$16,AO7,$Q$16,",",AN7,",",Q8,")") -> if(ai2="Western Utah",6,if(ai2="North",7,if(ai2="South",8,if(ai2="East",9,if(ai2="West",10,if(ai2="Not From America",11,0)))))) | U7: =D6 -> I did not grow up in the state of Utah | Y7: =E6 -> 14 | AA7: =G6 -> 21-25 students | AC7: =_xlfn.FLOOR.MATH(J30/5+0.2) -> 5 | AE7: =Sheet1!R7 -> New York | AI7: =IF(AE7="Weber","Eastern Utah",IF(AE7="Wayne","Eastern Utah",IF(AE7="Washington","Western Utah",IF(AE7="Wasatch","Eastern Utah",IF(AE7="Uintah","Eastern Utah",IF(AE7="Tooele","Midwest Utah",IF(AE7="Summit","Eastern Utah",IF(AE7="Springville","South East Utah County",IF(AE7="Sevier","Midwest Utah",IF(AE7="Saratoga Springs","North East Utah County",IF(AE7="Sanpete","Midwest Utah",IF(AE7="San Juan","Midwest Utah",IF(AE7="Salt Lake","Eastern Utah",IF(AE7="Rich","Eastern Utah",IF(AE7="Provo","Western Utah County",IF(AE7="Pleasant Grove","South East Utah County",IF(AE7="Piute","Midwest Utah",IF(AE7="Payson","South East Utah County",IF(AE7="Orem","South East Utah County",IF(AE7="Ogden","Western Utah County",IF(AE7="Morgan","Eastern Utah",IF(AE7="Millard","Midwest Utah",IF(AE7="Lindon","South East Utah County",IF(AE7="Layton","North East Utah County",IF(AE7="Kane","Western Utah",IF(AE7="Juab","Midwest Utah",IF(AE7="Iron","Western Utah",IF(AE7="I did not grow up in the state of Utah","South",IF(AE7="Herriman","Western Utah County",IF(AE7="Grand","Eastern Utah",IF(AE7="Garfield","Midwest Utah",IF(AE7="Emery","Eastern Utah",IF(AE7="Eagle Mountain","Western Utah County",IF(AE7="Duchesne","Eastern Utah",IF(AE7="Davis","Eastern Utah",IF(AE7="Daggett","Eastern Utah",IF(AE7="Carbon","Eastern Utah",IF(AE7="Cache","Midwest Utah",IF(AE7="Box Elder","Midwest Utah",IF(AE7="Beaver","Western Utah",IF(AE7="American Fork","North East Utah County",IF(AE7="Washington State","West",IF(AE7="Virginia","South",IF(AE7="Texas","South",IF(AE7="South Carolina","South",IF(AE7="Phoenix, Arizona","North",IF(AE7="Pennsylvania","East",IF(AE7="Ohio","North",IF(AE7="North Carolina","South",IF(AE7="New York","East",IF(AE7="New Jersey","East",IF(AE7="Nevada","West",IF(AE7="Massachusetts","East",IF(AE7="Lake Havasu, Arizona","West",IF(AE7="Iowa","North",IF(AE7="Idaho","West",IF(AE7="Hawaii","West",IF(AE7="Gilbert, Arizona","South",IF(AE7="Foreign Country","Not From America",IF(AE7="California","West",IF(AE7="Arkansas","North",IF(AE7="Alaska","West","x")))))))))))))))))))))))))))))))))))))))))))))))))))))))))))))) -> East | AL7: =IF(AI7="North East Utah County",1,IF(AI7="South East Utah County",2,IF(AI7="Western Utah County",3,IF(AI7="Eastern Utah",4,IF(AI7="Midwest Utah",5,IF(AI7="Western Utah",6,IF(AI7="North",7,IF(AI7="South",8,IF(AI7="East",9,IF(AI7="West",10,IF(AI7="Not From America",11,0))))))))))) -> 9 | AN7: =1+AN6 -> 6 | AO7: Western Utah
A8: Duchesne | B8: =1+B7 -> 8 | C8: =_xlfn.CONCAT(C7,"if(d1=",$Q$16,A8,$Q$16,",",B8,",") -> if(d1="American Fork",1,if(d1="Beaver",2,if(d1="Box Elder",3,if(d1="Cache",4,if(d1="Carbon",5,if(d1="Daggett",6,if(d1="Davis",7,if(d1="Duchesne",8, | D8: =Sheet1!P9 -> Salt Lake | E8: =IF(D8="American Fork",1,IF(D8="Beaver",2,IF(D8="Box Elder",3,IF(D8="Cache",4,IF(D8="Carbon",5,IF(D8="Daggett",6,IF(D8="Davis",7,IF(D8="Duchesne",8,IF(D8="Eagle Mountain",9,IF(D8="Emery",10,IF(D8="Garfield",11,IF(D8="Grand",12,IF(D8="Herriman",13,IF(D8="I did not grow up in the state of Utah",14,IF(D8="Iron",15,IF(D8="Juab",16,IF(D8="Kane",17,IF(D8="Layton",18,IF(D8="Lindon",19,IF(D8="Millard",20,IF(D8="Morgan",21,IF(D8="Ogden",22,IF(D8="Orem",23,IF(D8="Payson",24,IF(D8="Piute",25,IF(D8="Pleasant Grove",26,IF(D8="Provo",27,IF(D8="Rich",28,IF(D8="Salt Lake",29,IF(D8="San Juan",30,IF(D8="Sanpete",31,IF(D8="Saratoga Springs",32,IF(D8="Sevier",33,IF(D8="Springville",34,IF(D8="Summit",35,IF(D8="Tooele",36,IF(D8="Uintah",37,IF(D8="Wasatch",38,IF(D8="Washington",39,IF(D8="Wayne",40,41)))))))))))))))))))))))))))))))))))))))) -> 29 | G8: =Sheet1!O9 -> 16-20 students | J8: =J7+5 -> 40 | K8: =_xlfn.CONCAT(J8-4,"-",J8," students") -> 36-40 students | Q8: =_xlfn.CONCAT("if(ai2=",$Q$16,AO8,$Q$16,",",AN8,",",Q9,")") -> if(ai2="North",7,if(ai2="South",8,if(ai2="East",9,if(ai2="West",10,if(ai2="Not From America",11,0))))) | U8: =D7 -> I did not grow up in the state of Utah | Y8: =E7 -> 14 | AA8: =G7 -> 26-30 students | AC8: =_xlfn.FLOOR.MATH(J31/5+0.2) -> 6 | AE8: =Sheet1!R8 -> Foreign Country | AI8: =IF(AE8="Weber","Eastern Utah",IF(AE8="Wayne","Eastern Utah",IF(AE8="Washington","Western Utah",IF(AE8="Wasatch","Eastern Utah",IF(AE8="Uintah","Eastern Utah",IF(AE8="Tooele","Midwest Utah",IF(AE8="Summit","Eastern Utah",IF(AE8="Springville","South East Utah County",IF(AE8="Sevier","Midwest Utah",IF(AE8="Saratoga Springs","North East Utah County",IF(AE8="Sanpete","Midwest Utah",IF(AE8="San Juan","Midwest Utah",IF(AE8="Salt Lake","Eastern Utah",IF(AE8="Rich","Eastern Utah",IF(AE8="Provo","Western Utah County",IF(AE8="Pleasant Grove","South East Utah County",IF(AE8="Piute","Midwest Utah",IF(AE8="Payson","South East Utah County",IF(AE8="Orem","South East Utah County",IF(AE8="Ogden","Western Utah County",IF(AE8="Morgan","Eastern Utah",IF(AE8="Millard","Midwest Utah",IF(AE8="Lindon","South East Utah County",IF(AE8="Layton","North East Utah County",IF(AE8="Kane","Western Utah",IF(AE8="Juab","Midwest Utah",IF(AE8="Iron","Western Utah",IF(AE8="I did not grow up in the state of Utah","South",IF(AE8="Herriman","Western Utah County",IF(AE8="Grand","Eastern Utah",IF(AE8="Garfield","Midwest Utah",IF(AE8="Emery","Eastern Utah",IF(AE8="Eagle Mountain","Western Utah County",IF(AE8="Duchesne","Eastern Utah",IF(AE8="Davis","Eastern Utah",IF(AE8="Daggett","Eastern Utah",IF(AE8="Carbon","Eastern Utah",IF(AE8="Cache","Midwest Utah",IF(AE8="Box Elder","Midwest Utah",IF(AE8="Beaver","Western Utah",IF(AE8="American Fork","North East Utah County",IF(AE8="Washington State","West",IF(AE8="Virginia","South",IF(AE8="Texas","South",IF(AE8="South Carolina","South",IF(AE8="Phoenix, Arizona","North",IF(AE8="Pennsylvania","East",IF(AE8="Ohio","North",IF(AE8="North Carolina","South",IF(AE8="New York","East",IF(AE8="New Jersey","East",IF(AE8="Nevada","West",IF(AE8="Massachusetts","East",IF(AE8="Lake Havasu, Arizona","West",IF(AE8="Iowa","North",IF(AE8="Idaho","West",IF(AE8="Hawaii","West",IF(AE8="Gilbert, Arizona","South",IF(AE8="Foreign Country","Not From America",IF(AE8="California","West",IF(AE8="Arkansas","North",IF(AE8="Alaska","West","x")))))))))))))))))))))))))))))))))))))))))))))))))))))))))))))) -> Not From America | AL8: =IF(AI8="North East Utah County",1,IF(AI8="South East Utah County",2,IF(AI8="Western Utah County",3,IF(AI8="Eastern Utah",4,IF(AI8="Midwest Utah",5,IF(AI8="Western Utah",6,IF(AI8="North",7,IF(AI8="South",8,IF(AI8="East",9,IF(AI8="West",10,IF(AI8="Not From America",11,0))))))))))) -> 11 | AN8: =1+AN7 -> 7 | AO8: North
A9: Eagle Mountain | B9: =1+B8 -> 9 | C9: =_xlfn.CONCAT(C8,"if(d1=",$Q$16,A9,$Q$16,",",B9,",") -> if(d1="American Fork",1,if(d1="Beaver",2,if(d1="Box Elder",3,if(d1="Cache",4,if(d1="Carbon",5,if(d1="Daggett",6,if(d1="Davis",7,if(d1="Duchesne",8,if(d1="Eagle Mountain",9, | D9: =Sheet1!P10 -> I did not grow up in the state of Utah | E9: =IF(D9="American Fork",1,IF(D9="Beaver",2,IF(D9="Box Elder",3,IF(D9="Cache",4,IF(D9="Carbon",5,IF(D9="Daggett",6,IF(D9="Davis",7,IF(D9="Duchesne",8,IF(D9="Eagle Mountain",9,IF(D9="Emery",10,IF(D9="Garfield",11,IF(D9="Grand",12,IF(D9="Herriman",13,IF(D9="I did not grow up in the state of Utah",14,IF(D9="Iron",15,IF(D9="Juab",16,IF(D9="Kane",17,IF(D9="Layton",18,IF(D9="Lindon",19,IF(D9="Millard",20,IF(D9="Morgan",21,IF(D9="Ogden",22,IF(D9="Orem",23,IF(D9="Payson",24,IF(D9="Piute",25,IF(D9="Pleasant Grove",26,IF(D9="Provo",27,IF(D9="Rich",28,IF(D9="Salt Lake",29,IF(D9="San Juan",30,IF(D9="Sanpete",31,IF(D9="Saratoga Springs",32,IF(D9="Sevier",33,IF(D9="Springville",34,IF(D9="Summit",35,IF(D9="Tooele",36,IF(D9="Uintah",37,IF(D9="Wasatch",38,IF(D9="Washington",39,IF(D9="Wayne",40,41)))))))))))))))))))))))))))))))))))))))) -> 14 | G9: =Sheet1!O10 -> 26-30 students | J9: =J8+5 -> 45 | K9: =_xlfn.CONCAT(J9-4,"-",J9," students") -> 41-45 students | Q9: =_xlfn.CONCAT("if(ai2=",$Q$16,AO9,$Q$16,",",AN9,",",Q10,")") -> if(ai2="South",8,if(ai2="East",9,if(ai2="West",10,if(ai2="Not From America",11,0)))) | U9: =D8 -> Salt Lake | Y9: =E8 -> 29 | AA9: =G8 -> 16-20 students | AC9: =_xlfn.FLOOR.MATH(J32/5+0.2) -> 4 | AE9: =Sheet1!R9 -> Salt Lake | AI9: =IF(AE9="Weber","Eastern Utah",IF(AE9="Wayne","Eastern Utah",IF(AE9="Washington","Western Utah",IF(AE9="Wasatch","Eastern Utah",IF(AE9="Uintah","Eastern Utah",IF(AE9="Tooele","Midwest Utah",IF(AE9="Summit","Eastern Utah",IF(AE9="Springville","South East Utah County",IF(AE9="Sevier","Midwest Utah",IF(AE9="Saratoga Springs","North East Utah County",IF(AE9="Sanpete","Midwest Utah",IF(AE9="San Juan","Midwest Utah",IF(AE9="Salt Lake","Eastern Utah",IF(AE9="Rich","Eastern Utah",IF(AE9="Provo","Western Utah County",IF(AE9="Pleasant Grove","South East Utah County",IF(AE9="Piute","Midwest Utah",IF(AE9="Payson","South East Utah County",IF(AE9="Orem","South East Utah County",IF(AE9="Ogden","Western Utah County",IF(AE9="Morgan","Eastern Utah",IF(AE9="Millard","Midwest Utah",IF(AE9="Lindon","South East Utah County",IF(AE9="Layton","North East Utah County",IF(AE9="Kane","Western Utah",IF(AE9="Juab","Midwest Utah",IF(AE9="Iron","Western Utah",IF(AE9="I did not grow up in the state of Utah","South",IF(AE9="Herriman","Western Utah County",IF(AE9="Grand","Eastern Utah",IF(AE9="Garfield","Midwest Utah",IF(AE9="Emery","Eastern Utah",IF(AE9="Eagle Mountain","Western Utah County",IF(AE9="Duchesne","Eastern Utah",IF(AE9="Davis","Eastern Utah",IF(AE9="Daggett","Eastern Utah",IF(AE9="Carbon","Eastern Utah",IF(AE9="Cache","Midwest Utah",IF(AE9="Box Elder","Midwest Utah",IF(AE9="Beaver","Western Utah",IF(AE9="American Fork","North East Utah County",IF(AE9="Washington State","West",IF(AE9="Virginia","South",IF(AE9="Texas","South",IF(AE9="South Carolina","South",IF(AE9="Phoenix, Arizona","North",IF(AE9="Pennsylvania","East",IF(AE9="Ohio","North",IF(AE9="North Carolina","South",IF(AE9="New York","East",IF(AE9="New Jersey","East",IF(AE9="Nevada","West",IF(AE9="Massachusetts","East",IF(AE9="Lake Havasu, Arizona","West",IF(AE9="Iowa","North",IF(AE9="Idaho","West",IF(AE9="Hawaii","West",IF(AE9="Gilbert, Arizona","South",IF(AE9="Foreign Country","Not From America",IF(AE9="California","West",IF(AE9="Arkansas","North",IF(AE9="Alaska","West","x")))))))))))))))))))))))))))))))))))))))))))))))))))))))))))))) -> Eastern Utah | AL9: =IF(AI9="North East Utah County",1,IF(AI9="South East Utah County",2,IF(AI9="Western Utah County",3,IF(AI9="Eastern Utah",4,IF(AI9="Midwest Utah",5,IF(AI9="Western Utah",6,IF(AI9="North",7,IF(AI9="South",8,IF(AI9="East",9,IF(AI9="West",10,IF(AI9="Not From America",11,0))))))))))) -> 4 | AN9: =1+AN8 -> 8 | AO9: South
A10: Emery | B10: =1+B9 -> 10 | C10: =_xlfn.CONCAT(C9,"if(d1=",$Q$16,A10,$Q$16,",",B10,",") -> if(d1="American Fork",1,if(d1="Beaver",2,if(d1="Box Elder",3,if(d1="Cache",4,if(d1="Carbon",5,if(d1="Daggett",6,if(d1="Davis",7,if(d1="Duchesne",8,if(d1="Eagle Mountain",9,if(d1="Emery",10, | D10: =Sheet1!P11 -> I did not grow up in the state of Utah | E10: =IF(D10="American Fork",1,IF(D10="Beaver",2,IF(D10="Box Elder",3,IF(D10="Cache",4,IF(D10="Carbon",5,IF(D10="Daggett",6,IF(D10="Davis",7,IF(D10="Duchesne",8,IF(D10="Eagle Mountain",9,IF(D10="Emery",10,IF(D10="Garfield",11,IF(D10="Grand",12,IF(D10="Herriman",13,IF(D10="I did not grow up in the state of Utah",14,IF(D10="Iron",15,IF(D10="Juab",16,IF(D10="Kane",17,IF(D10="Layton",18,IF(D10="Lindon",19,IF(D10="Millard",20,IF(D10="Morgan",21,IF(D10="Ogden",22,IF(D10="Orem",23,IF(D10="Payson",24,IF(D10="Piute",25,IF(D10="Pleasant Grove",26,IF(D10="Provo",27,IF(D10="Rich",28,IF(D10="Salt Lake",29,IF(D10="San Juan",30,IF(D10="Sanpete",31,IF(D10="Saratoga Springs",32,IF(D10="Sevier",33,IF(D10="Springville",34,IF(D10="Summit",35,IF(D10="Tooele",36,IF(D10="Uintah",37,IF(D10="Wasatch",38,IF(D10="Washington",39,IF(D10="Wayne",40,41)))))))))))))))))))))))))))))))))))))))) -> 14 | G10: =Sheet1!O11 -> 26-30 students | J10: =J9+5 -> 50 | K10: =_xlfn.CONCAT(J10-4,"-",J10," students") -> 46-50 students | Q10: =_xlfn.CONCAT("if(ai2=",$Q$16,AO10,$Q$16,",",AN10,",",Q11,")") -> if(ai2="East",9,if(ai2="West",10,if(ai2="Not From America",11,0))) | U10: =D9 -> I did not grow up in the state of Utah | Y10: =E9 -> 14 | AA10: =G9 -> 26-30 students | AC10: =_xlfn.FLOOR.MATH(J33/5+0.2) -> 6 | AE10: =Sheet1!R10 -> Lake Havasu, Arizona | AI10: =IF(AE10="Weber","Eastern Utah",IF(AE10="Wayne","Eastern Utah",IF(AE10="Washington","Western Utah",IF(AE10="Wasatch","Eastern Utah",IF(AE10="Uintah","Eastern Utah",IF(AE10="Tooele","Midwest Utah",IF(AE10="Summit","Eastern Utah",IF(AE10="Springville","South East Utah County",IF(AE10="Sevier","Midwest Utah",IF(AE10="Saratoga Springs","North East Utah County",IF(AE10="Sanpete","Midwest Utah",IF(AE10="San Juan","Midwest Utah",IF(AE10="Salt Lake","Eastern Utah",IF(AE10="Rich","Eastern Utah",IF(AE10="Provo","Western Utah County",IF(AE10="Pleasant Grove","South East Utah County",IF(AE10="Piute","Midwest Utah",IF(AE10="Payson","South East Utah County",IF(AE10="Orem","South East Utah County",IF(AE10="Ogden","Western Utah County",IF(AE10="Morgan","Eastern Utah",IF(AE10="Millard","Midwest Utah",IF(AE10="Lindon","South East Utah County",IF(AE10="Layton","North East Utah County",IF(AE10="Kane","Western Utah",IF(AE10="Juab","Midwest Utah",IF(AE10="Iron","Western Utah",IF(AE10="I did not grow up in the state of Utah","South",IF(AE10="Herriman","Western Utah County",IF(AE10="Grand","Eastern Utah",IF(AE10="Garfield","Midwest Utah",IF(AE10="Emery","Eastern Utah",IF(AE10="Eagle Mountain","Western Utah County",IF(AE10="Duchesne","Eastern Utah",IF(AE10="Davis","Eastern Utah",IF(AE10="Daggett","Eastern Utah",IF(AE10="Carbon","Eastern Utah",IF(AE10="Cache","Midwest Utah",IF(AE10="Box Elder","Midwest Utah",IF(AE10="Beaver","Western Utah",IF(AE10="American Fork","North East Utah County",IF(AE10="Washington State","West",IF(AE10="Virginia","South",IF(AE10="Texas","South",IF(AE10="South Carolina","South",IF(AE10="Phoenix, Arizona","North",IF(AE10="Pennsylvania","East",IF(AE10="Ohio","North",IF(AE10="North Carolina","South",IF(AE10="New York","East",IF(AE10="New Jersey","East",IF(AE10="Nevada","West",IF(AE10="Massachusetts","East",IF(AE10="Lake Havasu, Arizona","West",IF(AE10="Iowa","North",IF(AE10="Idaho","West",IF(AE10="Hawaii","West",IF(AE10="Gilbert, Arizona","South",IF(AE10="Foreign Country","Not From America",IF(AE10="California","West",IF(AE10="Arkansas","North",IF(AE10="Alaska","West","x")))))))))))))))))))))))))))))))))))))))))))))))))))))))))))))) -> West | AL10: =IF(AI10="North East Utah County",1,IF(AI10="South East Utah County",2,IF(AI10="Western Utah County",3,IF(AI10="Eastern Utah",4,IF(AI10="Midwest Utah",5,IF(AI10="Western Utah",6,IF(AI10="North",7,IF(AI10="South",8,IF(AI10="East",9,IF(AI10="West",10,IF(AI10="Not From America",11,0))))))))))) -> 10 | AN10: =1+AN9 -> 9 | AO10: East
A11: Garfield | B11: =1+B10 -> 11 | C11: =_xlfn.CONCAT(C10,"if(d1=",$Q$16,A11,$Q$16,",",B11,",") -> if(d1="American Fork",1,if(d1="Beaver",2,if(d1="Box Elder",3,if(d1="Cache",4,if(d1="Carbon",5,if(d1="Daggett",6,if(d1="Davis",7,if(d1="Duchesne",8,if(d1="Eagle Mountain",9,if(d1="Emery",10,if(d1="Garfield",11, | D11: =Sheet1!P12 -> I did not grow up in the state of Utah | E11: =IF(D11="American Fork",1,IF(D11="Beaver",2,IF(D11="Box Elder",3,IF(D11="Cache",4,IF(D11="Carbon",5,IF(D11="Daggett",6,IF(D11="Davis",7,IF(D11="Duchesne",8,IF(D11="Eagle Mountain",9,IF(D11="Emery",10,IF(D11="Garfield",11,IF(D11="Grand",12,IF(D11="Herriman",13,IF(D11="I did not grow up in the state of Utah",14,IF(D11="Iron",15,IF(D11="Juab",16,IF(D11="Kane",17,IF(D11="Layton",18,IF(D11="Lindon",19,IF(D11="Millard",20,IF(D11="Morgan",21,IF(D11="Ogden",22,IF(D11="Orem",23,IF(D11="Payson",24,IF(D11="Piute",25,IF(D11="Pleasant Grove",26,IF(D11="Provo",27,IF(D11="Rich",28,IF(D11="Salt Lake",29,IF(D11="San Juan",30,IF(D11="Sanpete",31,IF(D11="Saratoga Springs",32,IF(D11="Sevier",33,IF(D11="Springville",34,IF(D11="Summit",35,IF(D11="Tooele",36,IF(D11="Uintah",37,IF(D11="Wasatch",38,IF(D11="Washington",39,IF(D11="Wayne",40,41)))))))))))))))))))))))))))))))))))))))) -> 14 | G11: =Sheet1!O12 -> 26-30 students | J11: =J10+5 -> 55 | K11: =AA101 -> 51 or more students | Q11: =_xlfn.CONCAT("if(ai2=",$Q$16,AO11,$Q$16,",",AN11,",",Q12,")") -> if(ai2="West",10,if(ai2="Not From America",11,0)) | U11: =D10 -> I did not grow up in the state of Utah | Y11: =E10 -> 14 | AA11: =G10 -> 26-30 students | AC11: =_xlfn.FLOOR.MATH(J34/5+0.2) -> 6 | AE11: =Sheet1!R11 -> New Jersey | AI11: =IF(AE11="Weber","Eastern Utah",IF(AE11="Wayne","Eastern Utah",IF(AE11="Washington","Western Utah",IF(AE11="Wasatch","Eastern Utah",IF(AE11="Uintah","Eastern Utah",IF(AE11="Tooele","Midwest Utah",IF(AE11="Summit","Eastern Utah",IF(AE11="Springville","South East Utah County",IF(AE11="Sevier","Midwest Utah",IF(AE11="Saratoga Springs","North East Utah County",IF(AE11="Sanpete","Midwest Utah",IF(AE11="San Juan","Midwest Utah",IF(AE11="Salt Lake","Eastern Utah",IF(AE11="Rich","Eastern Utah",IF(AE11="Provo","Western Utah County",IF(AE11="Pleasant Grove","South East Utah County",IF(AE11="Piute","Midwest Utah",IF(AE11="Payson","South East Utah County",IF(AE11="Orem","South East Utah County",IF(AE11="Ogden","Western Utah County",IF(AE11="Morgan","Eastern Utah",IF(AE11="Millard","Midwest Utah",IF(AE11="Lindon","South East Utah County",IF(AE11="Layton","North East Utah County",IF(AE11="Kane","Western Utah",IF(AE11="Juab","Midwest Utah",IF(AE11="Iron","Western Utah",IF(AE11="I did not grow up in the state of Utah","South",IF(AE11="Herriman","Western Utah County",IF(AE11="Grand","Eastern Utah",IF(AE11="Garfield","Midwest Utah",IF(AE11="Emery","Eastern Utah",IF(AE11="Eagle Mountain","Western Utah County",IF(AE11="Duchesne","Eastern Utah",IF(AE11="Davis","Eastern Utah",IF(AE11="Daggett","Eastern Utah",IF(AE11="Carbon","Eastern Utah",IF(AE11="Cache","Midwest Utah",IF(AE11="Box Elder","Midwest Utah",IF(AE11="Beaver","Western Utah",IF(AE11="American Fork","North East Utah County",IF(AE11="Washington State","West",IF(AE11="Virginia","South",IF(AE11="Texas","South",IF(AE11="South Carolina","South",IF(AE11="Phoenix, Arizona","North",IF(AE11="Pennsylvania","East",IF(AE11="Ohio","North",IF(AE11="North Carolina","South",IF(AE11="New York","East",IF(AE11="New Jersey","East",IF(AE11="Nevada","West",IF(AE11="Massachusetts","East",IF(AE11="Lake Havasu, Arizona","West",IF(AE11="Iowa","North",IF(AE11="Idaho","West",IF(AE11="Hawaii","West",IF(AE11="Gilbert, Arizona","South",IF(AE11="Foreign Country","Not From America",IF(AE11="California","West",IF(AE11="Arkansas","North",IF(AE11="Alaska","West","x")))))))))))))))))))))))))))))))))))))))))))))))))))))))))))))) -> East | AL11: =IF(AI11="North East Utah County",1,IF(AI11="South East Utah County",2,IF(AI11="Western Utah County",3,IF(AI11="Eastern Utah",4,IF(AI11="Midwest Utah",5,IF(AI11="Western Utah",6,IF(AI11="North",7,IF(AI11="South",8,IF(AI11="East",9,IF(AI11="West",10,IF(AI11="Not From America",11,0))))))))))) -> 9 | AN11: =1+AN10 -> 10 | AO11: West
